<?xml version="1.0" encoding="utf-8"?>
<!-- This URDF was automatically created by SolidWorks to URDF Exporter! Originally created by Stephen Brawner (brawner@gmail.com) 
     Commit Version: 1.5.1-0-g916b5db  Build Version: 1.5.7152.31018
     For more information, please see http://wiki.ros.org/sw_urdf_exporter -->
<robot
  name="virtual_arm">
  <link name="world"/>

  <joint name="fixed" type="fixed">
    <parent link="world"/>
    <child link="base_link"/>
  </joint>

  <link
    name="base_link">
    <inertial>
      <origin
        xyz="1.0408E-17 6.9389E-18 8.3267E-17"
        rpy="0 0 0" />
      <mass
        value="0.67456" />
      <inertia
        ixx="4.6301E-05"
        ixy="9.9716E-21"
        ixz="-1.574E-19"
        iyy="0.11934"
        iyz="2.2747E-21"
        izz="0.11936" />
    </inertial>
    <visual>
      <origin
        xyz="0 0 0"
        rpy="0 0 0" />
      <geometry>
        <mesh
          filename="package://virtual_arm_description/meshes/base_link.STL" />
      </geometry>
      <material
        name="">
        <color
          rgba="1 1 1 1" />
      </material>
    </visual>
    <collision>
      <origin
        xyz="0 0 0"
        rpy="0 0 0" />
      <geometry>
        <mesh
          filename="package://virtual_arm_description/meshes/base_link.STL" />
      </geometry>
    </collision>
  </link>
  <link
    name="link1">
    <inertial>
      <origin
        xyz="0.023073 0.0076445 -0.054712"
        rpy="0 0 0" />
      <mass
        value="0.68444" />
      <inertia
        ixx="0.0018803"
        ixy="-3.6845E-07"
        ixz="-2.0077E-07"
        iyy="0.0015575"
        iyz="7.6862E-05"
        izz="0.0026543" />
    </inertial>
    <visual>
      <origin
        xyz="0 0 0"
        rpy="0 0 0" />
      <geometry>
        <mesh
          filename="package://virtual_arm_description/meshes/link1.STL" />
      </geometry>
      <material
        name="">
        <color
          rgba="1 1 1 1" />
      </material>
    </visual>
    <collision>
      <origin
        xyz="0 0 0"
        rpy="0 0 0" />
      <geometry>
        <mesh
          filename="package://virtual_arm_description/meshes/link1.STL" />
      </geometry>
    </collision>
  </link>
  <joint
    name="Joint1"
    type="prismatic">
    <origin
      xyz="0 0 0"
      rpy="3.14 0 0" />
    <parent
      link="base_link" />
    <child
      link="link1" />
    <axis
      xyz="1 0 0" />
    <limit
      lower="-0.75"
      upper="0.75"
      effort="100"
      velocity="3" />
  </joint>
  <link
    name="link2">
    <inertial>
      <origin
        xyz="-0.000914427661184533 -0.00309491771933679 -0.0570864508587369"
        rpy="0 0 0" />
      <mass
        value="0.30141699445104" />
      <inertia
        ixx="0.000213414517445558"
        ixy="3.73007261360871E-08"
        ixz="2.00667415336531E-07"
        iyy="0.000198178986421146"
        iyz="-1.34308430586079E-05"
        izz="0.000314966704185689" />
    </inertial>
    <visual>
      <origin
        xyz="0 0 0"
        rpy="0 0 0" />
      <geometry>
        <mesh
          filename="package://virtual_arm_description/meshes/link2.STL" />
      </geometry>
      <material
        name="">
        <color
          rgba="1 1 1 1" />
      </material>
    </visual>
    <collision>
      <origin
        xyz="0 0 0"
        rpy="0 0 0" />
      <geometry>
        <mesh
          filename="package://virtual_arm_description/meshes/link2.STL" />
      </geometry>
    </collision>
  </link>
  <joint
    name="Joint2"
    type="revolute">
    <origin
      xyz="0.023118 0.034422 -0.13325"
      rpy="0 0 0" />
    <parent
      link="link1" />
    <child
      link="link2" />
    <axis
      xyz="0 0 1" />
    <limit
      lower="-1.57"
      upper="1.57"
      effort="100"
      velocity="6.28" />
  </joint>
  <link
    name="link3">
    <inertial>
      <origin
        xyz="-0.0020696 0.0010887 -0.18127"
        rpy="0 0 0" />
      <mass
        value="0.13799" />
      <inertia
        ixx="0.00034661"
        ixy="-5.8466E-09"
        ixz="-1.4193E-08"
        iyy="0.00039279"
        iyz="-2.2492E-06"
        izz="7.9146E-05" />
    </inertial>
    <visual>
      <origin
        xyz="0 0 0"
        rpy="0 0 0" />
      <geometry>
        <mesh
          filename="package://virtual_arm_description/meshes/link3.STL" />
      </geometry>
      <material
        name="">
        <color
          rgba="1 1 1 1" />
      </material>
    </visual>
    <collision>
      <origin
        xyz="0 0 0"
        rpy="0 0 0" />
      <geometry>
        <mesh
          filename="package://virtual_arm_description/meshes/link3.STL" />
      </geometry>
    </collision>
  </link>
  <joint
    name="Joint3"
    type="revolute">
    <origin
      xyz="0.00075 0.022 -0.085"
      rpy="0 0 0" />
    <parent
      link="link2" />
    <child
      link="link3" />
    <axis
      xyz="1 0 0" />
    <limit
      lower="-0.5233"
      upper="1.50"
      effort="100"
      velocity="6.28" />
  </joint>
  <link
    name="link4">
    <inertial>
      <origin
        xyz="-0.0010239 -0.00027037 -0.12528"
        rpy="0 0 0" />
      <mass
        value="0.12194" />
      <inertia
        ixx="0.00027763"
        ixy="1.5871E-09"
        ixz="-6.7075E-09"
        iyy="0.00032452"
        iyz="-2.4078E-06"
        izz="7.6284E-05" />
    </inertial>
    <visual>
      <origin
        xyz="0 0 0"
        rpy="0 0 0" />
      <geometry>
        <mesh
          filename="package://virtual_arm_description/meshes/link4.STL" />
      </geometry>
      <material
        name="">
        <color
          rgba="1 1 1 1" />
      </material>
    </visual>
    <collision>
      <origin
        xyz="0 0 0"
        rpy="0 0 0" />
      <geometry>
        <mesh
          filename="package://virtual_arm_description/meshes/link4.STL" />
      </geometry>
    </collision>
  </link>
  <joint
    name="Joint4"
    type="revolute">
    <origin
      xyz="0.00065 0.0061428 -0.2801"
      rpy="0 0 0" />
    <parent
      link="link3" />
    <child
      link="link4" />
    <axis
      xyz="1 0 0" />
    <limit
      lower="0.5233"
      upper="2.442"
      effort="100"
      velocity="6.28" />
  </joint>
  <link
    name="link5">
    <inertial>
      <origin
        xyz="0.0013951 0.00073632 -0.050475"
        rpy="0 0 0" />
      <mass
        value="0.053343" />
      <inertia
        ixx="1.5937E-05"
        ixy="5.9612E-10"
        ixz="-6.4266E-09"
        iyy="9.0492E-06"
        iyz="6.6726E-08"
        izz="1.7385E-05" />
    </inertial>
    <visual>
      <origin
        xyz="0 0 0"
        rpy="0 0 0" />
      <geometry>
        <mesh
          filename="package://virtual_arm_description/meshes/link5.STL" />
      </geometry>
      <material
        name="">
        <color
          rgba="1 1 1 1" />
      </material>
    </visual>
    <collision>
      <origin
        xyz="0 0 0"
        rpy="0 0 0" />
      <geometry>
        <mesh
          filename="package://virtual_arm_description/meshes/link5.STL" />
      </geometry>
    </collision>
  </link>
  <joint
    name="Joint5"
    type="revolute">
    <origin
      xyz="-0.0011 0.0018045 -0.20327"
      rpy="0 0 0" />
    <parent
      link="link4" />
    <child
      link="link5" />
    <axis
      xyz="1 0 0" />
    <limit
      lower="-1.2613"
      upper="1.16937"
      effort="100"
      velocity="6.28" />
  </joint>
  <link
    name="link6">
    <inertial>
      <origin
        xyz="-0.0013137 -0.00040015 -0.10964"
        rpy="0 0 0" />
      <mass
        value="0.3139" />
      <inertia
        ixx="0.0011379"
        ixy="-5.9635E-08"
        ixz="-2.8912E-06"
        iyy="0.00088015"
        iyz="-5.3171E-09"
        izz="0.00027448" />
    </inertial>
    <visual>
      <origin
        xyz="0 0 0"
        rpy="0 0 0" />
      <geometry>
        <mesh
          filename="package://virtual_arm_description/meshes/link6.STL" />
      </geometry>
      <material
        name="">
        <color
          rgba="1 1 1 1" />
      </material>
    </visual>
    <collision>
      <origin
        xyz="0 0 0"
        rpy="0 0 0" />
      <geometry>
        <mesh
          filename="package://virtual_arm_description/meshes/link6.STL" />
      </geometry>
    </collision>
  </link>
  <joint
    name="Joint6"
    type="revolute">
    <origin
      xyz="0.0015 0.01 -0.085"
      rpy="0 0 0" />
    <parent
      link="link5" />
    <child
      link="link6" />
    <axis
      xyz="0 0 1" />
    <limit
      lower="-1.57"
      upper="1.57"
      effort="100"
      velocity="6.28" />
  </joint>

  <transmission name="tran11">
    <type>transmission_interface/SimpleTransmission</type>
    <joint name="Joint1">
      <hardwareInterface>hardware_interface/PositionJointInterface</hardwareInterface>
    </joint>
    <actuator name="motor11">
      <hardwareInterface>hardware_interface/PositionJointInterface</hardwareInterface>
      <mechanicalReduction>1</mechanicalReduction>
    </actuator>
  </transmission>

  <transmission name="tran22">
    <type>transmission_interface/SimpleTransmission</type>
    <joint name="Joint2">
      <hardwareInterface>hardware_interface/PositionJointInterface</hardwareInterface>
    </joint>
    <actuator name="motor22">
      <hardwareInterface>hardware_interface/PositionJointInterface</hardwareInterface>
      <mechanicalReduction>1</mechanicalReduction>
    </actuator>
  </transmission>

  <transmission name="tran33">
    <type>transmission_interface/SimpleTransmission</type>
    <joint name="Joint3">
      <hardwareInterface>hardware_interface/PositionJointInterface</hardwareInterface>
    </joint>
    <actuator name="motor33">
      <hardwareInterface>hardware_interface/PositionJointInterface</hardwareInterface>
      <mechanicalReduction>1</mechanicalReduction>
    </actuator>
  </transmission>

  <transmission name="tran44">
    <type>transmission_interface/SimpleTransmission</type>
    <joint name="Joint4">
      <hardwareInterface>hardware_interface/PositionJointInterface</hardwareInterface>
    </joint>
    <actuator name="motor44">
      <hardwareInterface>hardware_interface/PositionJointInterface</hardwareInterface>
      <mechanicalReduction>1</mechanicalReduction>
    </actuator>
  </transmission>

  <transmission name="tran55">
    <type>transmission_interface/SimpleTransmission</type>
    <joint name="Joint5">
      <hardwareInterface>hardware_interface/PositionJointInterface</hardwareInterface>
    </joint>
    <actuator name="motor55">
      <hardwareInterface>hardware_interface/PositionJointInterface</hardwareInterface>
      <mechanicalReduction>1</mechanicalReduction>
    </actuator>
  </transmission>

  <transmission name="tran66">
    <type>transmission_interface/SimpleTransmission</type>
    <joint name="Joint6">
      <hardwareInterface>hardware_interface/PositionJointInterface</hardwareInterface>
    </joint>
    <actuator name="motor66">
      <hardwareInterface>hardware_interface/PositionJointInterface</hardwareInterface>
      <mechanicalReduction>1</mechanicalReduction>
    </actuator>
  </transmission>
  <gazebo>
    <plugin name="gazebo_ros_control" filename="libgazebo_ros_control.so">
      <robotNamespace>/virtual_arm</robotNamespace>
      <robotSimType>gazebo_ros_control/DefaultRobotHWSim</robotSimType> 
    </plugin>
  </gazebo>
  <gazebo reference="link6">
    <collision>
      <surface>
        <contact>
          <ode>
	    <max_vel>20</max_vel>
	    <min_depth>0.0001</min_depth>
          </ode>
	</contact>
	<friction>
	  <ode>
	    <mu>0.9</mu>
	    <mu2>0.4</mu2>
	  </ode>
        </friction>
        <bounce>
          <restitution_coefficient>0.9</restitution_coefficient>
          <threshold>0.001</threshold>
        </bounce>
      </surface>
    </collision>
  </gazebo>
</robot>
